"""
Authentication utilities for password hashing and JWT handling
"""

import os
import jwt
from datetime import datetime, timedelta, timezone
from typing import Optional, Union
from passlib.context import CryptContext
from fastapi import HTTPException, status
from pydantic import ValidationError

from app.schemas.auth import TokenData


# Password hashing configuration
pwd_context = CryptContext(schemes=["bcrypt"], deprecated="auto")

# JWT configuration
SECRET_KEY = os.getenv("SECRET_KEY", "your-secret-key-change-in-production")
ALGORITHM = "HS256"
ACCESS_TOKEN_EXPIRE_MINUTES = 30


def verify_password(plain_password: str, hashed_password: str) -> bool:
    """Verify a password against its hash"""
    return pwd_context.verify(plain_password, hashed_password)


def get_password_hash(password: str) -> str:
    """Hash a password"""
    return pwd_context.hash(password)


def create_access_token(data: dict, expires_delta: Optional[timedelta] = None) -> str:
    """Create a JWT access token"""
    to_encode = data.copy()
    
    if expires_delta:
        expire = datetime.now(timezone.utc) + expires_delta
    else:
        expire = datetime.now(timezone.utc) + timedelta(minutes=ACCESS_TOKEN_EXPIRE_MINUTES)
    
    to_encode.update({"exp": expire})
    encoded_jwt = jwt.encode(to_encode, SECRET_KEY, algorithm=ALGORITHM)
    return encoded_jwt


def verify_token(token: str) -> TokenData:
    """Verify and decode a JWT token"""
    credentials_exception = HTTPException(
        status_code=status.HTTP_401_UNAUTHORIZED,
        detail="Could not validate credentials",
        headers={"WWW-Authenticate": "Bearer"},
    )
    
    try:
        payload = jwt.decode(token, SECRET_KEY, algorithms=[ALGORITHM])
        user_id: str = payload.get("sub")
        email: str = payload.get("email")
        
        if user_id is None:
            raise credentials_exception
            
        token_data = TokenData(user_id=user_id, email=email)
        return token_data
        
    except (jwt.PyJWTError, ValidationError):
        raise credentials_exception